<!-- <?xml version="1.0" encoding="utf-8"?> -->
<!-- This URDF was automatically created by SolidWorks to URDF Exporter! Originally created by Stephen Brawner (brawner@gmail.com) 
     Commit Version: 1.6.0-4-g7f85cfe  Build Version: 1.6.7995.38578
     For more information, please see http://wiki.ros.org/sw_urdf_exporter -->
<robot
  name="antipodal_model_lite">
  <link
    name="base_link">
    <inertial>
      <origin
        xyz="-0.0322222222222222 -1.22557628497596E-17 1.64649087730448E-18"
        rpy="0 0 0" />
      <mass
        value="0.072" />
      <inertia
        ixx="0.0001392"
        ixy="6.03382302378959E-22"
        ixz="-2.56205408394758E-22"
        iyy="7.64444444444444E-06"
        iyz="-1.40168864996214E-21"
        izz="0.000142044444444444" />
    </inertial>
    <visual>
      <origin
        xyz="0 0 0"
        rpy="0 0 0" />
      <geometry>
        <mesh
          filename="base_link.STL" />
      </geometry>
      <material
        name="">
        <color
          rgba="1 1 1 1" />
      </material>
    </visual>
    <collision>
      <origin
        xyz="0 0 0"
        rpy="0 0 0" />
      <geometry>
        <mesh
          filename="base_link.STL" />
      </geometry>
    </collision>
  </link>
  <link
    name="finger1">
    <inertial>
      <origin
        xyz="-0.0097474 -0.040386 1.197E-19"
        rpy="0 0 0" />
      <mass
        value="0.032796" />
      <inertia
        ixx="1.8509E-05"
        ixy="1.2941E-07"
        ixz="1.5086E-22"
        iyy="2.244E-06"
        iyz="-5.5469E-23"
        izz="1.8567E-05" />
    </inertial>
    <visual>
      <origin
        xyz="0 0 0"
        rpy="0 0 0" />
      <geometry>
        <mesh
          filename="finger1.STL" />
      </geometry>
      <material
        name="">
        <color
          rgba="1 1 1 1" />
      </material>
    </visual>
    <collision>
      <origin
        xyz="0 0 0"
        rpy="0 0 0" />
      <geometry>
        <mesh
          filename="finger1.STL" />
      </geometry>
    </collision>
  </link>
  <joint
    name="finger1_joint"
    type="prismatic">
    <origin
      xyz="-0.02 -0.06 0"
      rpy="0 0 1.5708" />
    <parent
      link="base_link" />
    <child
      link="finger1" />
    <axis
      xyz="1 0 0" />
    <limit
      lower="0"
      upper="0.06"
      effort="1"
      velocity="1" />
  </joint>
  <link
    name="finger2">
    <inertial>
      <origin
        xyz="-0.0097474 -0.040386 1.0781E-20"
        rpy="0 0 0" />
      <mass
        value="0.032796" />
      <inertia
        ixx="1.8509E-05"
        ixy="1.2941E-07"
        ixz="-1.3184E-23"
        iyy="2.244E-06"
        iyz="-6.5404E-23"
        izz="1.8567E-05" />
    </inertial>
    <visual>
      <origin
        xyz="0 0 0"
        rpy="0 0 0" />
      <geometry>
        <mesh
          filename="finger2.STL" />
      </geometry>
      <material
        name="">
        <color
          rgba="1 1 1 1" />
      </material>
    </visual>
    <collision>
      <origin
        xyz="0 0 0"
        rpy="0 0 0" />
      <geometry>
        <mesh
          filename="finger2.STL" />
      </geometry>
    </collision>
  </link>
  <joint
    name="finger2_joint"
    type="prismatic">
    <origin
      xyz="-0.02 0.06 0"
      rpy="3.1416 0 -1.5708" />
    <parent
      link="base_link" />
    <child
      link="finger2" />
    <axis
      xyz="1 0 0" />
    <limit
      lower="0"
      upper="0.06"
      effort="1"
      velocity="1" />
  </joint>
</robot>